---------- Begin SLURM Prolog ----------
Job ID:        3826277
Username:      ddepew
Accountname:   lc_ddd2
Name:          Workflow_R47_Take1
Partition:     scavenge
Nodelist:      hpc[3002,3012-3014]
TasksPerNode:  8(x4)
CPUsPerTask:   Default[1]
TMPDIR:        /tmp/3826277.scavenge
SCRATCHDIR:    /staging/scratch/3826277
Cluster:       uschpc
HSDA Account:  false
---------- 2019-07-03 12:18:12 ---------
Starting 3826277 Wed Jul 3 12:18:12 PDT 2019
Initiated on hpc3002

Running on 4 nodes: 
hpc[3002,3012-3014]
Using 32 compute processes with 8 compute processes per node
Traceback (most recent call last):
  File "testMain.py", line 3, in <module>
    sys.stderr(sys.argv[1])
TypeError: '_io.TextIOWrapper' object is not callable
Traceback (most recent call last):
  File "testMain.py", line 3, in <module>
    sys.stderr(sys.argv[1])
TypeError: '_io.TextIOWrapper' object is not callable
Traceback (most recent call last):
  File "testMain.py", line 3, in <module>
    sys.stderr(sys.argv[1])
TypeError: '_io.TextIOWrapper' object is not callable
Traceback (most recent call last):
  File "testMain.py", line 3, in <module>
    sys.stderr(sys.argv[1])
TypeError: '_io.TextIOWrapper' object is not callable
Traceback (most recent call last):
  File "testMain.py", line 3, in <module>
    sys.stderr(sys.argv[1])
TypeError: '_io.TextIOWrapper' object is not callable
Traceback (most recent call last):
  File "testMain.py", line 3, in <module>
    sys.stderr(sys.argv[1])
TypeError: '_io.TextIOWrapper' object is not callable
Traceback (most recent call last):
  File "testMain.py", line 3, in <module>
    sys.stderr(sys.argv[1])
TypeError: '_io.TextIOWrapper' object is not callable
Traceback (most recent call last):
  File "testMain.py", line 3, in <module>
    sys.stderr(sys.argv[1])
TypeError: '_io.TextIOWrapper' object is not callable
Traceback (most recent call last):
  File "testMain.py", line 3, in <module>
    sys.stderr(sys.argv[1])
TypeError: '_io.TextIOWrapper' object is not callable
Traceback (most recent call last):
  File "testMain.py", line 3, in <module>
    sys.stderr(sys.argv[1])
TypeError: '_io.TextIOWrapper' object is not callable
Traceback (most recent call last):
  File "testMain.py", line 3, in <module>
    sys.stderr(sys.argv[1])
TypeError: '_io.TextIOWrapper' object is not callable
Traceback (most recent call last):
  File "testMain.py", line 3, in <module>
    sys.stderr(sys.argv[1])
TypeError: '_io.TextIOWrapper' object is not callable
Traceback (most recent call last):
  File "testMain.py", line 3, in <module>
    sys.stderr(sys.argv[1])
TypeError: '_io.TextIOWrapper' object is not callable
Traceback (most recent call last):
  File "testMain.py", line 3, in <module>
    sys.stderr(sys.argv[1])
TypeError: '_io.TextIOWrapper' object is not callable
Traceback (most recent call last):
  File "testMain.py", line 3, in <module>
    sys.stderr(sys.argv[1])
TypeError: '_io.TextIOWrapper' object is not callable
Traceback (most recent call last):
  File "testMain.py", line 3, in <module>
    sys.stderr(sys.argv[1])
TypeError: '_io.TextIOWrapper' object is not callable
Traceback (most recent call last):
  File "testMain.py", line 3, in <module>
    sys.stderr(sys.argv[1])
TypeError: '_io.TextIOWrapper' object is not callable
Traceback (most recent call last):
  File "testMain.py", line 3, in <module>
    sys.stderr(sys.argv[1])
TypeError: '_io.TextIOWrapper' object is not callable
Traceback (most recent call last):
  File "testMain.py", line 3, in <module>
    sys.stderr(sys.argv[1])
TypeError: '_io.TextIOWrapper' object is not callable
Traceback (most recent call last):
  File "testMain.py", line 3, in <module>
    sys.stderr(sys.argv[1])
TypeError: '_io.TextIOWrapper' object is not callable
Traceback (most recent call last):
  File "testMain.py", line 3, in <module>
    sys.stderr(sys.argv[1])
TypeError: '_io.TextIOWrapper' object is not callable
Traceback (most recent call last):
  File "testMain.py", line 3, in <module>
    sys.stderr(sys.argv[1])
TypeError: '_io.TextIOWrapper' object is not callable
Traceback (most recent call last):
  File "testMain.py", line 3, in <module>
    sys.stderr(sys.argv[1])
TypeError: '_io.TextIOWrapper' object is not callable
Traceback (most recent call last):
  File "testMain.py", line 3, in <module>
    sys.stderr(sys.argv[1])
TypeError: '_io.TextIOWrapper' object is not callable
Traceback (most recent call last):
  File "testMain.py", line 3, in <module>
    sys.stderr(sys.argv[1])
TypeError: '_io.TextIOWrapper' object is not callable
Traceback (most recent call last):
  File "testMain.py", line 3, in <module>
    sys.stderr(sys.argv[1])
TypeError: '_io.TextIOWrapper' object is not callable
Traceback (most recent call last):
  File "testMain.py", line 3, in <module>
    sys.stderr(sys.argv[1])
TypeError: '_io.TextIOWrapper' object is not callable
Traceback (most recent call last):
  File "testMain.py", line 3, in <module>
    sys.stderr(sys.argv[1])
TypeError: '_io.TextIOWrapper' object is not callable
Traceback (most recent call last):
  File "testMain.py", line 3, in <module>
    sys.stderr(sys.argv[1])
TypeError: '_io.TextIOWrapper' object is not callable
Traceback (most recent call last):
  File "testMain.py", line 3, in <module>
    sys.stderr(sys.argv[1])
TypeError: '_io.TextIOWrapper' object is not callable
Traceback (most recent call last):
  File "testMain.py", line 3, in <module>
    sys.stderr(sys.argv[1])
TypeError: '_io.TextIOWrapper' object is not callable
Traceback (most recent call last):
  File "testMain.py", line 3, in <module>
    sys.stderr(sys.argv[1])
TypeError: '_io.TextIOWrapper' object is not callable
Traceback (most recent call last):
  File "testMain.py", line 3, in <module>
    sys.stderr(sys.argv[1])
TypeError: '_io.TextIOWrapper' object is not callable
Traceback (most recent call last):
  File "testMain.py", line 3, in <module>
    sys.stderr(sys.argv[1])
TypeError: '_io.TextIOWrapper' object is not callable
Traceback (most recent call last):
  File "testMain.py", line 3, in <module>
    sys.stderr(sys.argv[1])
TypeError: '_io.TextIOWrapper' object is not callable
Traceback (most recent call last):
  File "testMain.py", line 3, in <module>
    sys.stderr(sys.argv[1])
TypeError: '_io.TextIOWrapper' object is not callable
Traceback (most recent call last):
  File "testMain.py", line 3, in <module>
    sys.stderr(sys.argv[1])
TypeError: '_io.TextIOWrapper' object is not callable
Traceback (most recent call last):
  File "testMain.py", line 3, in <module>
    sys.stderr(sys.argv[1])
TypeError: '_io.TextIOWrapper' object is not callable
Traceback (most recent call last):
  File "testMain.py", line 3, in <module>
    sys.stderr(sys.argv[1])
TypeError: '_io.TextIOWrapper' object is not callable
Traceback (most recent call last):
  File "testMain.py", line 3, in <module>
    sys.stderr(sys.argv[1])
TypeError: '_io.TextIOWrapper' object is not callable
Traceback (most recent call last):
  File "testMain.py", line 3, in <module>
    sys.stderr(sys.argv[1])
TypeError: '_io.TextIOWrapper' object is not callable
Traceback (most recent call last):
  File "testMain.py", line 3, in <module>
    sys.stderr(sys.argv[1])
TypeError: '_io.TextIOWrapper' object is not callable
Traceback (most recent call last):
  File "testMain.py", line 3, in <module>
    sys.stderr(sys.argv[1])
TypeError: '_io.TextIOWrapper' object is not callable
Traceback (most recent call last):
  File "testMain.py", line 3, in <module>
    sys.stderr(sys.argv[1])
TypeError: '_io.TextIOWrapper' object is not callable
Traceback (most recent call last):
  File "testMain.py", line 3, in <module>
    sys.stderr(sys.argv[1])
TypeError: '_io.TextIOWrapper' object is not callable
Traceback (most recent call last):
  File "testMain.py", line 3, in <module>
    sys.stderr(sys.argv[1])
TypeError: '_io.TextIOWrapper' object is not callable
Traceback (most recent call last):
  File "testMain.py", line 3, in <module>
    sys.stderr(sys.argv[1])
TypeError: '_io.TextIOWrapper' object is not callable
Traceback (most recent call last):
  File "testMain.py", line 3, in <module>
    sys.stderr(sys.argv[1])
TypeError: '_io.TextIOWrapper' object is not callable
Traceback (most recent call last):
  File "testMain.py", line 3, in <module>
    sys.stderr(sys.argv[1])
TypeError: '_io.TextIOWrapper' object is not callable
Traceback (most recent call last):
  File "testMain.py", line 3, in <module>
    sys.stderr(sys.argv[1])
TypeError: '_io.TextIOWrapper' object is not callable
Traceback (most recent call last):
  File "testMain.py", line 3, in <module>
    sys.stderr(sys.argv[1])
TypeError: '_io.TextIOWrapper' object is not callable
Traceback (most recent call last):
  File "testMain.py", line 3, in <module>
    sys.stderr(sys.argv[1])
TypeError: '_io.TextIOWrapper' object is not callable
Traceback (most recent call last):
  File "testMain.py", line 3, in <module>
    sys.stderr(sys.argv[1])
TypeError: '_io.TextIOWrapper' object is not callable
Traceback (most recent call last):
  File "testMain.py", line 3, in <module>
    sys.stderr(sys.argv[1])
TypeError: '_io.TextIOWrapper' object is not callable
Traceback (most recent call last):
  File "testMain.py", line 3, in <module>
    sys.stderr(sys.argv[1])
TypeError: '_io.TextIOWrapper' object is not callable
Traceback (most recent call last):
  File "testMain.py", line 3, in <module>
    sys.stderr(sys.argv[1])
TypeError: '_io.TextIOWrapper' object is not callable
Traceback (most recent call last):
  File "testMain.py", line 3, in <module>
    sys.stderr(sys.argv[1])
TypeError: '_io.TextIOWrapper' object is not callable
Traceback (most recent call last):
  File "testMain.py", line 3, in <module>
    sys.stderr(sys.argv[1])
TypeError: '_io.TextIOWrapper' object is not callable
Traceback (most recent call last):
  File "testMain.py", line 3, in <module>
    sys.stderr(sys.argv[1])
TypeError: '_io.TextIOWrapper' object is not callable
Traceback (most recent call last):
  File "testMain.py", line 3, in <module>
    sys.stderr(sys.argv[1])
TypeError: '_io.TextIOWrapper' object is not callable
Traceback (most recent call last):
  File "testMain.py", line 3, in <module>
    sys.stderr(sys.argv[1])
TypeError: '_io.TextIOWrapper' object is not callable
Traceback (most recent call last):
  File "testMain.py", line 3, in <module>
    sys.stderr(sys.argv[1])
TypeError: '_io.TextIOWrapper' object is not callable
Traceback (most recent call last):
  File "testMain.py", line 3, in <module>
    sys.stderr(sys.argv[1])
TypeError: '_io.TextIOWrapper' object is not callable
Traceback (most recent call last):
  File "testMain.py", line 3, in <module>
    sys.stderr(sys.argv[1])
TypeError: '_io.TextIOWrapper' object is not callable
Traceback (most recent call last):
  File "testMain.py", line 3, in <module>
    sys.stderr(sys.argv[1])
TypeError: '_io.TextIOWrapper' object is not callable
Traceback (most recent call last):
  File "testMain.py", line 3, in <module>
    sys.stderr(sys.argv[1])
TypeError: '_io.TextIOWrapper' object is not callable
Traceback (most recent call last):
  File "testMain.py", line 3, in <module>
    sys.stderr(sys.argv[1])
TypeError: '_io.TextIOWrapper' object is not callable
Traceback (most recent call last):
  File "testMain.py", line 3, in <module>
    sys.stderr(sys.argv[1])
TypeError: '_io.TextIOWrapper' object is not callable
Traceback (most recent call last):
  File "testMain.py", line 3, in <module>
    sys.stderr(sys.argv[1])
TypeError: '_io.TextIOWrapper' object is not callable
Traceback (most recent call last):
  File "testMain.py", line 3, in <module>
    sys.stderr(sys.argv[1])
TypeError: '_io.TextIOWrapper' object is not callable
Traceback (most recent call last):
  File "testMain.py", line 3, in <module>
    sys.stderr(sys.argv[1])
TypeError: '_io.TextIOWrapper' object is not callable
Traceback (most recent call last):
  File "testMain.py", line 3, in <module>
    sys.stderr(sys.argv[1])
TypeError: '_io.TextIOWrapper' object is not callable
Traceback (most recent call last):
  File "testMain.py", line 3, in <module>
    sys.stderr(sys.argv[1])
TypeError: '_io.TextIOWrapper' object is not callable
Traceback (most recent call last):
  File "testMain.py", line 3, in <module>
    sys.stderr(sys.argv[1])
TypeError: '_io.TextIOWrapper' object is not callable
Traceback (most recent call last):
  File "testMain.py", line 3, in <module>
    sys.stderr(sys.argv[1])
TypeError: '_io.TextIOWrapper' object is not callable
Traceback (most recent call last):
  File "testMain.py", line 3, in <module>
    sys.stderr(sys.argv[1])
TypeError: '_io.TextIOWrapper' object is not callable
Traceback (most recent call last):
  File "testMain.py", line 3, in <module>
    sys.stderr(sys.argv[1])
TypeError: '_io.TextIOWrapper' object is not callable
Traceback (most recent call last):
  File "testMain.py", line 3, in <module>
    sys.stderr(sys.argv[1])
TypeError: '_io.TextIOWrapper' object is not callable
Traceback (most recent call last):
  File "testMain.py", line 3, in <module>
    sys.stderr(sys.argv[1])
TypeError: '_io.TextIOWrapper' object is not callable
Traceback (most recent call last):
  File "testMain.py", line 3, in <module>
    sys.stderr(sys.argv[1])
TypeError: '_io.TextIOWrapper' object is not callable
Traceback (most recent call last):
  File "testMain.py", line 3, in <module>
    sys.stderr(sys.argv[1])
TypeError: '_io.TextIOWrapper' object is not callable
Traceback (most recent call last):
  File "testMain.py", line 3, in <module>
    sys.stderr(sys.argv[1])
TypeError: '_io.TextIOWrapper' object is not callable
Traceback (most recent call last):
  File "testMain.py", line 3, in <module>
    sys.stderr(sys.argv[1])
TypeError: '_io.TextIOWrapper' object is not callable
Traceback (most recent call last):
  File "testMain.py", line 3, in <module>
    sys.stderr(sys.argv[1])
TypeError: '_io.TextIOWrapper' object is not callable
Traceback (most recent call last):
  File "testMain.py", line 3, in <module>
    sys.stderr(sys.argv[1])
TypeError: '_io.TextIOWrapper' object is not callable
Traceback (most recent call last):
  File "testMain.py", line 3, in <module>
    sys.stderr(sys.argv[1])
TypeError: '_io.TextIOWrapper' object is not callable
Traceback (most recent call last):
  File "testMain.py", line 3, in <module>
    sys.stderr(sys.argv[1])
TypeError: '_io.TextIOWrapper' object is not callable
Traceback (most recent call last):
  File "testMain.py", line 3, in <module>
    sys.stderr(sys.argv[1])
TypeError: '_io.TextIOWrapper' object is not callable
Traceback (most recent call last):
  File "testMain.py", line 3, in <module>
    sys.stderr(sys.argv[1])
TypeError: '_io.TextIOWrapper' object is not callable
Traceback (most recent call last):
  File "testMain.py", line 3, in <module>
    sys.stderr(sys.argv[1])
TypeError: '_io.TextIOWrapper' object is not callable
Traceback (most recent call last):
  File "testMain.py", line 3, in <module>
    sys.stderr(sys.argv[1])
TypeError: '_io.TextIOWrapper' object is not callable
Traceback (most recent call last):
  File "testMain.py", line 3, in <module>
    sys.stderr(sys.argv[1])
TypeError: '_io.TextIOWrapper' object is not callable
Traceback (most recent call last):
  File "testMain.py", line 3, in <module>
    sys.stderr(sys.argv[1])
TypeError: '_io.TextIOWrapper' object is not callable
Traceback (most recent call last):
  File "testMain.py", line 3, in <module>
    sys.stderr(sys.argv[1])
TypeError: '_io.TextIOWrapper' object is not callable
Traceback (most recent call last):
  File "testMain.py", line 3, in <module>
    sys.stderr(sys.argv[1])
TypeError: '_io.TextIOWrapper' object is not callable
Traceback (most recent call last):
  File "testMain.py", line 3, in <module>
    sys.stderr(sys.argv[1])
TypeError: '_io.TextIOWrapper' object is not callable
Traceback (most recent call last):
  File "testMain.py", line 3, in <module>
    sys.stderr(sys.argv[1])
TypeError: '_io.TextIOWrapper' object is not callable
Traceback (most recent call last):
  File "testMain.py", line 3, in <module>
    sys.stderr(sys.argv[1])
TypeError: '_io.TextIOWrapper' object is not callable
Traceback (most recent call last):
  File "testMain.py", line 3, in <module>
    sys.stderr(sys.argv[1])
TypeError: '_io.TextIOWrapper' object is not callable
Traceback (most recent call last):
  File "testMain.py", line 3, in <module>
    sys.stderr(sys.argv[1])
TypeError: '_io.TextIOWrapper' object is not callable
Traceback (most recent call last):
  File "testMain.py", line 3, in <module>
    sys.stderr(sys.argv[1])
TypeError: '_io.TextIOWrapper' object is not callable
Traceback (most recent call last):
  File "testMain.py", line 3, in <module>
    sys.stderr(sys.argv[1])
TypeError: '_io.TextIOWrapper' object is not callable
Traceback (most recent call last):
  File "testMain.py", line 3, in <module>
    sys.stderr(sys.argv[1])
TypeError: '_io.TextIOWrapper' object is not callable
Traceback (most recent call last):
  File "testMain.py", line 3, in <module>
    sys.stderr(sys.argv[1])
TypeError: '_io.TextIOWrapper' object is not callable
Traceback (most recent call last):
  File "testMain.py", line 3, in <module>
    sys.stderr(sys.argv[1])
TypeError: '_io.TextIOWrapper' object is not callable
Traceback (most recent call last):
  File "testMain.py", line 3, in <module>
    sys.stderr(sys.argv[1])
TypeError: '_io.TextIOWrapper' object is not callable
Traceback (most recent call last):
  File "testMain.py", line 3, in <module>
    sys.stderr(sys.argv[1])
TypeError: '_io.TextIOWrapper' object is not callable
Traceback (most recent call last):
  File "testMain.py", line 3, in <module>
    sys.stderr(sys.argv[1])
TypeError: '_io.TextIOWrapper' object is not callable
Traceback (most recent call last):
  File "testMain.py", line 3, in <module>
    sys.stderr(sys.argv[1])
TypeError: '_io.TextIOWrapper' object is not callable
Traceback (most recent call last):
  File "testMain.py", line 3, in <module>
    sys.stderr(sys.argv[1])
TypeError: '_io.TextIOWrapper' object is not callable
Traceback (most recent call last):
  File "testMain.py", line 3, in <module>
    sys.stderr(sys.argv[1])
TypeError: '_io.TextIOWrapper' object is not callable
Traceback (most recent call last):
  File "testMain.py", line 3, in <module>
    sys.stderr(sys.argv[1])
TypeError: '_io.TextIOWrapper' object is not callable
Traceback (most recent call last):
  File "testMain.py", line 3, in <module>
    sys.stderr(sys.argv[1])
TypeError: '_io.TextIOWrapper' object is not callable
Traceback (most recent call last):
  File "testMain.py", line 3, in <module>
    sys.stderr(sys.argv[1])
TypeError: '_io.TextIOWrapper' object is not callable
Traceback (most recent call last):
  File "testMain.py", line 3, in <module>
    sys.stderr(sys.argv[1])
TypeError: '_io.TextIOWrapper' object is not callable
Traceback (most recent call last):
  File "testMain.py", line 3, in <module>
    sys.stderr(sys.argv[1])
TypeError: '_io.TextIOWrapper' object is not callable
slurmstepd: error: *** JOB 3826277 ON hpc3002 CANCELLED AT 2019-07-03T12:18:33 ***
